{"uuid": "05246809-6f28-44dd-a73c-decc1bc96d9f", "children": ["3c068da6-71e5-4eb9-91e4-2497284bfa63"], "befores": [{"name": "start_appium_desired", "status": "broken", "statusDetails": {"message": "selenium.common.exceptions.WebDriverException: Message: An unknown server-side error occurred while processing the command. Original error: Cannot start the 'com.wljiam.yunzhiniao' application. Visit https://github.com/appium/appium/blob/master/docs/en/writing-running-appium/android/activity-startup.md for troubleshooting. Original error: Cannot start the 'com.wljiam.yunzhiniao' application. Visit https://github.com/appium/appium/blob/master/docs/en/writing-running-appium/android/activity-startup.md for troubleshooting. Original error: Activity name '.com.wljm.module_sign.activity.VerifyCodeLoginActivity' used to start the app doesn't exist or cannot be launched! Make sure it exists and is a launchable activity\nStacktrace:\nUnknownError: An unknown server-side error occurred while processing the command. Original error: Cannot start the 'com.wljiam.yunzhiniao' application. Visit https://github.com/appium/appium/blob/master/docs/en/writing-running-appium/android/activity-startup.md for troubleshooting. Original error: Cannot start the 'com.wljiam.yunzhiniao' application. Visit https://github.com/appium/appium/blob/master/docs/en/writing-running-appium/android/activity-startup.md for troubleshooting. Original error: Activity name '.com.wljm.module_sign.activity.VerifyCodeLoginActivity' used to start the app doesn't exist or cannot be launched! Make sure it exists and is a launchable activity\n    at getResponseForW3CError (C:\\Users\\Administrator\\AppData\\Local\\Programs\\Appium Server GUI\\resources\\app\\node_modules\\appium\\node_modules\\appium-base-driver\\lib\\protocol\\errors.js:804:9)\n    at asyncHandler (C:\\Users\\Administrator\\AppData\\Local\\Programs\\Appium Server GUI\\resources\\app\\node_modules\\appium\\node_modules\\appium-base-driver\\lib\\protocol\\protocol.js:380:37)\n", "trace": "  File \"D:\\Cyrpto_appium_api\\venv\\lib\\site-packages\\pluggy\\_callers.py\", line 39, in _multicall\n    res = hook_impl.function(*args)\n  File \"D:\\Cyrpto_appium_api\\venv\\lib\\site-packages\\_pytest\\fixtures.py\", line 1121, in pytest_fixture_setup\n    result = call_fixture_func(fixturefunc, request, kwargs)\n  File \"D:\\Cyrpto_appium_api\\venv\\lib\\site-packages\\_pytest\\fixtures.py\", line 893, in call_fixture_func\n    fixture_result = next(generator)\n  File \"D:\\Cyrpto_appium_api\\testcase\\conftest.py\", line 28, in start_appium_desired\n    driver = appium_desired_caps(host,port,system_port)\n  File \"D:\\Cyrpto_appium_api\\base\\DesireCaps.py\", line 39, in appium_desired_caps\n    driver = webdriver.Remote('http://%s:%s/wd/hub'%(host,port), desired_caps)\n  File \"D:\\Cyrpto_appium_api\\venv\\lib\\site-packages\\appium\\webdriver\\webdriver.py\", line 230, in __init__\n    super().__init__(\n  File \"D:\\Cyrpto_appium_api\\venv\\lib\\site-packages\\selenium\\webdriver\\remote\\webdriver.py\", line 272, in __init__\n    self.start_session(capabilities, browser_profile)\n  File \"D:\\Cyrpto_appium_api\\venv\\lib\\site-packages\\appium\\webdriver\\webdriver.py\", line 320, in start_session\n    response = self.execute(RemoteCommand.NEW_SESSION, w3c_caps)\n  File \"D:\\Cyrpto_appium_api\\venv\\lib\\site-packages\\selenium\\webdriver\\remote\\webdriver.py\", line 429, in execute\n    self.error_handler.check_response(response)\n  File \"D:\\Cyrpto_appium_api\\venv\\lib\\site-packages\\selenium\\webdriver\\remote\\errorhandler.py\", line 243, in check_response\n    raise exception_class(message, screen, stacktrace)\n"}, "start": 1664467244045, "stop": 1664467290263}], "start": 1664467244045, "stop": 1664467290549}