{"uuid": "710a8b44-94d8-4cd4-8f3b-05fd806e777e", "children": ["53ae5be4-cd30-47e1-9dd0-302d285febec"], "befores": [{"name": "start_appium_desired", "status": "broken", "statusDetails": {"message": "selenium.common.exceptions.WebDriverException: Message: An unknown server-side error occurred while processing the command. Original error: The application at 'D:\\Cyrpto_appium_api\\app\\yzn.apk' does not exist or is not accessible\nStacktrace:\nUnknownError: An unknown server-side error occurred while processing the command. Original error: The application at 'D:\\Cyrpto_appium_api\\app\\yzn.apk' does not exist or is not accessible\n    at getResponseForW3CError (C:\\Users\\Administrator\\AppData\\Local\\Programs\\Appium Server GUI\\resources\\app\\node_modules\\appium\\node_modules\\appium-base-driver\\lib\\protocol\\errors.js:804:9)\n    at asyncHandler (C:\\Users\\Administrator\\AppData\\Local\\Programs\\Appium Server GUI\\resources\\app\\node_modules\\appium\\node_modules\\appium-base-driver\\lib\\protocol\\protocol.js:380:37)\n", "trace": "  File \"D:\\Cyrpto_appium_api\\venv\\lib\\site-packages\\pluggy\\_callers.py\", line 39, in _multicall\n    res = hook_impl.function(*args)\n  File \"D:\\Cyrpto_appium_api\\venv\\lib\\site-packages\\_pytest\\fixtures.py\", line 1121, in pytest_fixture_setup\n    result = call_fixture_func(fixturefunc, request, kwargs)\n  File \"D:\\Cyrpto_appium_api\\venv\\lib\\site-packages\\_pytest\\fixtures.py\", line 893, in call_fixture_func\n    fixture_result = next(generator)\n  File \"D:\\Cyrpto_appium_api\\testcase\\conftest.py\", line 28, in start_appium_desired\n    driver = appium_desired_caps(host,port,system_port)\n  File \"D:\\Cyrpto_appium_api\\base\\DesireCaps.py\", line 39, in appium_desired_caps\n    driver = webdriver.Remote('http://%s:%s/wd/hub'%(host,port), desired_caps)\n  File \"D:\\Cyrpto_appium_api\\venv\\lib\\site-packages\\appium\\webdriver\\webdriver.py\", line 230, in __init__\n    super().__init__(\n  File \"D:\\Cyrpto_appium_api\\venv\\lib\\site-packages\\selenium\\webdriver\\remote\\webdriver.py\", line 272, in __init__\n    self.start_session(capabilities, browser_profile)\n  File \"D:\\Cyrpto_appium_api\\venv\\lib\\site-packages\\appium\\webdriver\\webdriver.py\", line 320, in start_session\n    response = self.execute(RemoteCommand.NEW_SESSION, w3c_caps)\n  File \"D:\\Cyrpto_appium_api\\venv\\lib\\site-packages\\selenium\\webdriver\\remote\\webdriver.py\", line 429, in execute\n    self.error_handler.check_response(response)\n  File \"D:\\Cyrpto_appium_api\\venv\\lib\\site-packages\\selenium\\webdriver\\remote\\errorhandler.py\", line 243, in check_response\n    raise exception_class(message, screen, stacktrace)\n"}, "start": 1664467051102, "stop": 1664467139161}], "start": 1664467051102, "stop": 1664467139638}